Workbook

Sheet template
A1: Developer Evaluation Template
A3: Employee Name: | G3: Review Period: | I3: Reviewer:
A4: Position/Level: | B4: Senior Developer | I4: Date:
A6: Section | B6: Subsection | C6: Criteria | D6: Description | E6: IC Rating | F6: Role Model Rating | G6: Weight | H6: Evidence/Examples | I6: Notes
A7: =weights_editor!A3 -> ENGINEERING CRAFT | E7: =(E8*G8+E13*G13+E19*G19+E24*G24+E30*G30+E37*G37) -> 1.505 | F7: =VLOOKUP(TRIM($B$4&$A$7&B7&C7),raw_weights!A:H,7,false) -> 2.5345 | G7: =VLOOKUP(TRIM($B$4&$A$7&B7&C7),raw_weights!A:H,8,false) -> 0.6
B8: =weights_editor!B4 -> Writing Code | D8: =VLOOKUP(TRIM($B$4&$A$7&B8&C8),raw_weights!A:I,9,false) -> The ability to contribute high quality code to production environments. Is able to consistently write production-ready code across large, complex projects. | E8: =E9*G9+E10*G10+E11*G11+E12*G12 -> 1 | F8: =VLOOKUP(TRIM($B$4&$A$7&B8&C8),raw_weights!A:H,7,false) -> 2.51 | G8: =VLOOKUP(TRIM($B$4&$A$7&B8&C8),raw_weights!A:H,8,false) -> 0.35
C9: =weights_editor!C5 -> Quality | D9: =VLOOKUP(TRIM($B$4&$A$7&$B$8&C9),raw_weights!A:I,9,false) -> You're regularly trusted to lead complex and business-critical coding projects, including guiding others. | E9: 1 | F9: =VLOOKUP(TRIM($B$4&$A$7&$B$8&C9),raw_weights!A:H,7,false) -> 2.6 | G9: =VLOOKUP(TRIM($B$4&$A$7&$B$8&C9),raw_weights!A:H,8,false) -> 0.4
C10: =weights_editor!C6 -> Documentation | D10: =VLOOKUP(TRIM($B$4&$A$7&$B$8&C10),raw_weights!A:I,9,false) -> Your code is consistently self-documenting where possible. You've regularly maintained, improved and extended existing documentation unprompted. | E10: 1 | F10: =VLOOKUP(TRIM($B$4&$A$7&$B$8&C10),raw_weights!A:H,7,false) -> 2.4 | G10: =VLOOKUP(TRIM($B$4&$A$7&$B$8&C10),raw_weights!A:H,8,false) -> 0.2
C11: =weights_editor!C7 -> Language | D11: =VLOOKUP(TRIM($B$4&$A$7&$B$8&C11),raw_weights!A:I,9,false) -> You're committing quality code in any language your team needs OR you're best in class at one language. | E11: 1 | F11: =VLOOKUP(TRIM($B$4&$A$7&$B$8&C11),raw_weights!A:H,7,false) -> 2.8 | G11: =VLOOKUP(TRIM($B$4&$A$7&$B$8&C11),raw_weights!A:H,8,false) -> 0.3
C12: =weights_editor!C8 -> Mentoring | D12: =VLOOKUP(TRIM($B$4&$A$7&$B$8&C12),raw_weights!A:I,9,false) -> You have mentored several junior engineers around code quality. | E12: 1 | F12: =VLOOKUP(TRIM($B$4&$A$7&$B$8&C12),raw_weights!A:H,7,false) -> 1.5 | G12: =VLOOKUP(TRIM($B$4&$A$7&$B$8&C12),raw_weights!A:H,8,false) -> 0.1
B13: =weights_editor!B9 -> Testing | D13: =VLOOKUP(TRIM($B$4&$A$7&B13&C13),raw_weights!A:I,9,false) -> The ability to understand and implement great testing practices. Independently testing, advising the rest of the team on quality of tests. | E13: =E14*G14+E15*G15+E16*G16+E17*G17+E18*G18 -> 1 | F13: =VLOOKUP(TRIM($B$4&$A$7&B13&C13),raw_weights!A:H,7,false) -> 2.92 | G13: =VLOOKUP(TRIM($B$4&$A$7&B13&C13),raw_weights!A:H,8,false) -> 0.15
C14: =weights_editor!C10 -> Testing your code | D14: =VLOOKUP(TRIM($B$4&$A$7&$B$13&C14),raw_weights!A:I,9,false) -> You always write full tests for your code unassisted, covering all edge cases even with complex functionality. | E14: 1 | F14: =VLOOKUP(TRIM($B$4&$A$7&$B$13&C14),raw_weights!A:H,7,false) -> 3.2 | G14: =VLOOKUP(TRIM($B$4&$A$7&$B$13&C14),raw_weights!A:H,8,false) -> 0.5
C15: =weights_editor!C11 -> Improving coverage | D15: =VLOOKUP(TRIM($B$4&$A$7&$B$13&C15),raw_weights!A:I,9,false) -> You've worked to improve the quality of your own and your team's test coverage. | E15: 1 | F15: =VLOOKUP(TRIM($B$4&$A$7&$B$13&C15),raw_weights!A:H,7,false) -> 2.8 | G15: =VLOOKUP(TRIM($B$4&$A$7&$B$13&C15),raw_weights!A:H,8,false) -> 0.3
C16: =weights_editor!C12 -> Taking responsibility | D16: =VLOOKUP(TRIM($B$4&$A$7&$B$13&C16),raw_weights!A:I,9,false) -> You consistently look for and can recall quality metrics to demonstrate your test coverage, and monitor in behalf of your team. | E16: 1 | F16: =VLOOKUP(TRIM($B$4&$A$7&$B$13&C16),raw_weights!A:H,7,false) -> 2.4 | G16: =VLOOKUP(TRIM($B$4&$A$7&$B$13&C16),raw_weights!A:H,8,false) -> 0.2
C17: =weights_editor!C13 -> Leading testing strategy | D17: =VLOOKUP(TRIM($B$4&$A$7&$B$13&C17),raw_weights!A:I,9,false) -> N/A | E17: 0 | F17: =VLOOKUP(TRIM($B$4&$A$7&$B$13&C17),raw_weights!A:H,7,false) -> 1 | G17: =VLOOKUP(TRIM($B$4&$A$7&$B$13&C17),raw_weights!A:H,8,false) -> 0
C18: =weights_editor!C14 -> Advocating for testing | D18: =VLOOKUP(TRIM($B$4&$A$7&$B$13&C18),raw_weights!A:I,9,false) -> N/A | E18: 0 | F18: =VLOOKUP(TRIM($B$4&$A$7&$B$13&C18),raw_weights!A:H,7,false) -> 1 | G18: =VLOOKUP(TRIM($B$4&$A$7&$B$13&C18),raw_weights!A:H,8,false) -> 0
B19: =weights_editor!B15 -> Technical Understanding & Prioritisation | D19: =VLOOKUP(TRIM($B$4&$A$7&B19&C19),raw_weights!A:I,9,false) -> The ability to develop technical understanding and use this to prioritise tasks appropriately. Is a technical and prioritisation leader within the team, including taking some ownership of other team members' technical growth and development. | E19: =E20*G20+E21*G21+E22*G22+E23*G23 -> 1.6 | F19: =VLOOKUP(TRIM($B$4&$A$7&B19&C19),raw_weights!A:H,7,false) -> 2.46 | G19: =VLOOKUP(TRIM($B$4&$A$7&B19&C19),raw_weights!A:H,8,false) -> 0.15
C20: =weights_editor!C16 -> Understanding code | D20: =VLOOKUP(TRIM($B$4&$A$7&$B$19&C20),raw_weights!A:I,9,false) -> You understand your team's domain at a high level, including the breadth of services, how they interact, and data flows between systems. You understand adjacent domains as they affect your team. | E20: 2 | F20: =VLOOKUP(TRIM($B$4&$A$7&$B$19&C20),raw_weights!A:H,7,false) -> 2.2 | G20: =VLOOKUP(TRIM($B$4&$A$7&$B$19&C20),raw_weights!A:H,8,false) -> 0.55
C21: =weights_editor!C17 -> Technical collaboration | D21: =VLOOKUP(TRIM($B$4&$A$7&$B$19&C21),raw_weights!A:I,9,false) -> You actively facilitate technical discussions between team members and have a deep familiarity with technical topics under discussion | E21: 1 | F21: =VLOOKUP(TRIM($B$4&$A$7&$B$19&C21),raw_weights!A:H,7,false) -> 2.6 | G21: =VLOOKUP(TRIM($B$4&$A$7&$B$19&C21),raw_weights!A:H,8,false) -> 0.25
C22: =weights_editor!C18 -> Work breakdown | D22: =VLOOKUP(TRIM($B$4&$A$7&$B$19&C22),raw_weights!A:I,9,false) -> You review projects critically, ensuring they are appropriately delineated and understood by the team. | E22: 1 | F22: =VLOOKUP(TRIM($B$4&$A$7&$B$19&C22),raw_weights!A:H,7,false) -> 2.4 | G22: =VLOOKUP(TRIM($B$4&$A$7&$B$19&C22),raw_weights!A:H,8,false) -> 0.15
C23: =weights_editor!C19 -> Task prioritisation | D23: =VLOOKUP(TRIM($B$4&$A$7&$B$19&C23),raw_weights!A:I,9,false) -> You ensure tasks are prioritised correctly, and that dependencies are noted and well understood by the team, including at the epic level. You foster a culture of priority setting and highlight the importance of alignment with organizational strategy | E23: 1 | F23: =VLOOKUP(TRIM($B$4&$A$7&$B$19&C23),raw_weights!A:H,7,false) -> 2.4 | G23: =VLOOKUP(TRIM($B$4&$A$7&$B$19&C23),raw_weights!A:H,8,false) -> 0.1
B24: =weights_editor!B20 -> Software Architecture | D24: =VLOOKUP(TRIM($B$4&$A$7&B24&C24),raw_weights!A:I,9,false) -> The ability to interact and engage with architectural approaches of the organization. Is able to consistently design code that is aligned with the overall service architecture. | E24: =E25*G25+E26*G26+E27*G27+E28*G28+E29*G29 -> 2.1 | F24: =VLOOKUP(TRIM($B$4&$A$7&B24&C24),raw_weights!A:H,7,false) -> 2.17 | G24: =VLOOKUP(TRIM($B$4&$A$7&B24&C24),raw_weights!A:H,8,false) -> 0.15
C25: =weights_editor!C21 -> Reaction to feedback | D25: =VLOOKUP(TRIM($B$4&$A$7&$B$24&C25),raw_weights!A:I,9,false) -> N/A | E25: 4 | F25: =VLOOKUP(TRIM($B$4&$A$7&$B$24&C25),raw_weights!A:H,7,false) -> 3 | G25: =VLOOKUP(TRIM($B$4&$A$7&$B$24&C25),raw_weights!A:H,8,false) -> 0.2
C26: =weights_editor!C22 -> Code | D26: =VLOOKUP(TRIM($B$4&$A$7&$B$24&C26),raw_weights!A:I,9,false) -> You are able to utilize abstractions and code isolation effectively. | E26: 2 | F26: =VLOOKUP(TRIM($B$4&$A$7&$B$24&C26),raw_weights!A:H,7,false) -> 2.6 | G26: =VLOOKUP(TRIM($B$4&$A$7&$B$24&C26),raw_weights!A:H,8,false) -> 0.2
C27: =weights_editor!C23 -> Design | D27: =VLOOKUP(TRIM($B$4&$A$7&$B$24&C27),raw_weights!A:I,9,false) -> You have deep architectural and design pattern experience. You consult with team members only on more difficult designs. You set up new projects to ensure architectural success by anticipating future use cases and making design decisions that minimize the cost of future changes | E27: 1 | F27: =VLOOKUP(TRIM($B$4&$A$7&$B$24&C27),raw_weights!A:H,7,false) -> 1.5 | G27: =VLOOKUP(TRIM($B$4&$A$7&$B$24&C27),raw_weights!A:H,8,false) -> 0.3
C28: =weights_editor!C24 -> Development | D28: =VLOOKUP(TRIM($B$4&$A$7&$B$24&C28),raw_weights!A:I,9,false) -> N/A | E28: 2 | F28: =VLOOKUP(TRIM($B$4&$A$7&$B$24&C28),raw_weights!A:H,7,false) -> 2 | G28: =VLOOKUP(TRIM($B$4&$A$7&$B$24&C28),raw_weights!A:H,8,false) -> 0.3
C29: =weights_editor!C25 -> Technical debt | D29: =VLOOKUP(TRIM($B$4&$A$7&$B$24&C29),raw_weights!A:I,9,false) -> You make plans with technical debt in mind, and how you will pay it down incrementally and consistently. You advise other team members on recognising and considering it | E29: 2 | F29: =VLOOKUP(TRIM($B$4&$A$7&$B$24&C29),raw_weights!A:H,7,false) -> 2.1 | G29: =VLOOKUP(TRIM($B$4&$A$7&$B$24&C29),raw_weights!A:H,8,false) -> 0
B30: =weights_editor!B26 -> Security | D30: =VLOOKUP(TRIM($B$4&$A$7&B30&C30),raw_weights!A:I,9,false) -> The ability to understand and apply security principles, handle user data appropriately and report security concerns. Consistently approaches all engineering work with a security lens. | E30: =E31*G31+E32*G32+E33*G33+E34*G34+E35*G35+E36*G36 -> 2.9 | F30: =VLOOKUP(TRIM($B$4&$A$7&B30&C30),raw_weights!A:H,7,false) -> 2.71 | G30: =VLOOKUP(TRIM($B$4&$A$7&B30&C30),raw_weights!A:H,8,false) -> 0.1
C31: =weights_editor!C27 -> Knowledge | D31: =VLOOKUP(TRIM($B$4&$A$7&$B$30&C31),raw_weights!A:I,9,false) -> You have an excellent understanding of security principles and you work to better facilitate the team's understanding. | E31: 4 | F31: =VLOOKUP(TRIM($B$4&$A$7&$B$30&C31),raw_weights!A:H,7,false) -> 2.8 | G31: =VLOOKUP(TRIM($B$4&$A$7&$B$30&C31),raw_weights!A:H,8,false) -> 0.3
C32: =weights_editor!C28 -> User data | D32: =VLOOKUP(TRIM($B$4&$A$7&$B$30&C32),raw_weights!A:I,9,false) -> You have faultless handling of user data, and set an example for others within the team. | E32: 3 | F32: =VLOOKUP(TRIM($B$4&$A$7&$B$30&C32),raw_weights!A:H,7,false) -> 3.1 | G32: =VLOOKUP(TRIM($B$4&$A$7&$B$30&C32),raw_weights!A:H,8,false) -> 0.3
C33: =weights_editor!C29 -> Reporting | D33: =VLOOKUP(TRIM($B$4&$A$7&$B$30&C33),raw_weights!A:I,9,false) -> N/A | E33: 2 | F33: =VLOOKUP(TRIM($B$4&$A$7&$B$30&C33),raw_weights!A:H,7,false) -> 2.6 | G33: =VLOOKUP(TRIM($B$4&$A$7&$B$30&C33),raw_weights!A:H,8,false) -> 0.2
C34: =weights_editor!C30 -> Proactivity | D34: =VLOOKUP(TRIM($B$4&$A$7&$B$30&C34),raw_weights!A:I,9,false) -> You actively look for security vulnerabilities both in the code and when providing peer reviews. | E34: 2 | F34: =VLOOKUP(TRIM($B$4&$A$7&$B$30&C34),raw_weights!A:H,7,false) -> 2.1 | G34: =VLOOKUP(TRIM($B$4&$A$7&$B$30&C34),raw_weights!A:H,8,false) -> 0.2
C35: =weights_editor!C31 -> Collaboration | D35: =VLOOKUP(TRIM($B$4&$A$7&$B$30&C35),raw_weights!A:I,9,false) -> You work with the security teams to help refine technical strategy. | E35: 1 | F35: =VLOOKUP(TRIM($B$4&$A$7&$B$30&C35),raw_weights!A:H,7,false) -> 2.4 | G35: =VLOOKUP(TRIM($B$4&$A$7&$B$30&C35),raw_weights!A:H,8,false) -> 0
C36: =weights_editor!C32 -> Strategy | D36: =VLOOKUP(TRIM($B$4&$A$7&$B$30&C36),raw_weights!A:I,9,false) -> N/A | E36: 2 | F36: =VLOOKUP(TRIM($B$4&$A$7&$B$30&C36),raw_weights!A:H,7,false) -> 1.5 | G36: =VLOOKUP(TRIM($B$4&$A$7&$B$30&C36),raw_weights!A:H,8,false) -> 0
B37: =weights_editor!B33 -> Debugging & Monitoring | D37: =VLOOKUP(TRIM($B$4&$A$7&B37&C37),raw_weights!A:I,9,false) -> The ability to understand and implement systematic debugging and monitoring practices to diagnose issues. Uses systematic debugging to diagnose all issues located to a single service and drives monitoring work across the team. | E37: =E38*G38+E39*G39+E40*G40+E41*G41+E42*G42+E43*G43 -> 1.6 | F37: =VLOOKUP(TRIM($B$4&$A$7&B37&C37),raw_weights!A:H,7,false) -> 2.525 | G37: =VLOOKUP(TRIM($B$4&$A$7&B37&C37),raw_weights!A:H,8,false) -> 0.1
C38: =weights_editor!C34 -> Debugging | D38: =VLOOKUP(TRIM($B$4&$A$7&$B$37&C38),raw_weights!A:I,9,false) -> You use systematic debugging to diagnose cross service issues, sometimes with help from more senior engineers. | E38: 2 | F38: =VLOOKUP(TRIM($B$4&$A$7&$B$37&C38),raw_weights!A:H,7,false) -> 2.8 | G38: =VLOOKUP(TRIM($B$4&$A$7&$B$37&C38),raw_weights!A:H,8,false) -> 0.4
C39: =weights_editor!C35 -> Tools | D39: =VLOOKUP(TRIM($B$4&$A$7&$B$37&C39),raw_weights!A:I,9,false) -> You can judge whether a new tool is necessary to instrument and monitor systems. You can create that tool if required. | E39: 2 | F39: =VLOOKUP(TRIM($B$4&$A$7&$B$37&C39),raw_weights!A:H,7,false) -> 2.6 | G39: =VLOOKUP(TRIM($B$4&$A$7&$B$37&C39),raw_weights!A:H,8,false) -> 0.2
C40: =weights_editor!C36 -> Philosophy | D40: =VLOOKUP(TRIM($B$4&$A$7&$B$37&C40),raw_weights!A:I,9,false) -> You understand the cross-functional and cross-organization implications of your team's monitoring philosophy. You proactively seek to refine the monitoring philosophy of your team. | E40: 1 | F40: =VLOOKUP(TRIM($B$4&$A$7&$B$37&C40),raw_weights!A:H,7,false) -> 2.1 | G40: =VLOOKUP(TRIM($B$4&$A$7&$B$37&C40),raw_weights!A:H,8,false) -> 0.2
C41: =weights_editor!C37 -> Data | D41: =VLOOKUP(TRIM($B$4&$A$7&$B$37&C41),raw_weights!A:I,9,false) -> You are aware of the operational data for your team and use it as a basis for driving changes to your team's services to achieve stability and performance improvements. | E41: 1 | F41: =VLOOKUP(TRIM($B$4&$A$7&$B$37&C41),raw_weights!A:H,7,false) -> 2.4 | G41: =VLOOKUP(TRIM($B$4&$A$7&$B$37&C41),raw_weights!A:H,8,false) -> 0.15
C42: =weights_editor!C38 -> Profiling | D42: =VLOOKUP(TRIM($B$4&$A$7&$B$37&C42),raw_weights!A:I,9,false) -> N/A | E42: 1 | F42: =VLOOKUP(TRIM($B$4&$A$7&$B$37&C42),raw_weights!A:H,7,false) -> 2.1 | G42: =VLOOKUP(TRIM($B$4&$A$7&$B$37&C42),raw_weights!A:H,8,false) -> 0.05
...

Sheet weights_editor
D1: Junior Developer | G1: Confirmed Developer | J1: Senior Developer | M1: Staff Developer | P1: Senior Staff Developer | S1: Principal Developer
A2: Section | B2: Subsection | C2: Criteria | D2: Role Model Rating | E2: Weight | G2: Role Model Rating | H2: Weight | J2: Role Model Rating | K2: Weight | M2: Role Model Rating | N2: Weight | P2: Role Model Rating | Q2: Weight | S2: Role Model Rating | T2: Weight
A3: ENGINEERING CRAFT | D3: =D4*E4+D9*E9+D15*E15+D20*E20+D26*E26+D33*E33 -> 1.26 | E3: 0.7 | G3: =G4*H4+G9*H9+G15*H15+G20*H20+G26*H26+G33*H33 -> 1.9675 | H3: 0.65 | J3: =J4*K4+J9*K9+J15*K15+J20*K20+J26*K26+J33*K33 -> 2.5345 | K3: 0.6 | M3: =M4*N4+M9*N9+M15*N15+M20*N20+M26*N26+M33*N33 -> 2.9905 | N3: 0.4 | P3: =P4*Q4+P9*Q9+P15*Q15+P20*Q20+P26*Q26+P33*Q33 -> 3.64475 | Q3: 0.4 | S3: =S4*T4+S9*T9+S15*T15+S20*T20+S26*T26+S33*T33 -> 4 | T3: 0.4
A4: ENGINEERING CRAFT | B4: Writing Code | D4: =D5*E5+D6*E6+D7*E7+D8*E8 -> 1.2 | E4: 0.45 | G4: =G5*H5+G6*H6+G7*H7+G8*H8 -> 1.925 | H4: 0.4 | J4: =J5*K5+J6*K6+J7*K7+J8*K8 -> 2.51 | K4: 0.35 | M4: =M5*N5+M6*N6+M7*N7+M8*N8 -> 3.15 | N4: 0.3 | P4: =P5*Q5+P6*Q6+P7*Q7+P8*Q8 -> 3.61 | Q4: 0.3 | S4: =S5*T5+S6*T6+S7*T7+S8*T8 -> 4 | T4: 0.3
A5: ENGINEERING CRAFT | B5: Writing Code | C5: Quality | D5: 1.2 | E5: 0.5 | G5: 2 | H5: 0.45 | J5: 2.6 | K5: 0.4 | M5: 3.2 | N5: 0.4 | P5: 3.6 | Q5: 0.4 | S5: 4 | T5: 0.4
A6: ENGINEERING CRAFT | B6: Writing Code | C6: Documentation | D6: 1 | E6: 0.25 | G6: 1.8 | H6: 0.25 | J6: 2.4 | K6: 0.2 | M6: 3 | N6: 0.2 | P6: 3.4 | Q6: 0.2 | S6: 4 | T6: 0.2
A7: ENGINEERING CRAFT | B7: Writing Code | C7: Language | D7: 1.4 | E7: 0.25 | G7: 2.2 | H7: 0.25 | J7: 2.8 | K7: 0.3 | M7: 3.4 | N7: 0.3 | P7: 3.8 | Q7: 0.3 | S7: 4 | T7: 0.3
A8: ENGINEERING CRAFT | B8: Writing Code | C8: Mentoring | D8: 0 | E8: 0 | G8: 0.5 | H8: 0.05 | J8: 1.5 | K8: 0.1 | M8: 2.5 | N8: 0.1 | P8: 3.5 | Q8: 0.1 | S8: 4 | T8: 0.1
A9: ENGINEERING CRAFT | B9: Testing | D9: =D10*E10+D11*E11+D12*E12+D13*E13+D14*E14 -> 1.7 | E9: 0.15 | G9: =G10*H10+G11*H11+G12*H12+G13*H13+G14*H14 -> 2.45 | H9: 0.15 | J9: =J10*K10+J11*K11+J12*K12+J13*K13+J14*K14 -> 2.92 | K9: 0.15 | M9: =M10*N10+M11*N11+M12*N12+M13*N13+M14*N14 -> 2.5 | N9: 0.15 | P9: =P10*Q10+P11*Q11+P12*Q12+P13*Q13+P14*Q14 -> 3.6 | Q9: 0.15 | S9: =S10*T10+S11*T11+S12*T12+S13*T13+S14*T14 -> 4 | T9: 0.15
A10: ENGINEERING CRAFT | B10: Testing | C10: Testing your code | D10: 2 | E10: 0.7 | G10: 2.8 | H10: 0.6 | J10: 3.2 | K10: 0.5 | M10: 3.6 | N10: 0 | Q10: 0 | T10: 0
A11: ENGINEERING CRAFT | B11: Testing | C11: Improving coverage | D11: 1 | E11: 0.2 | G11: 2 | H11: 0.25 | J11: 2.8 | K11: 0.3 | M11: 3.2 | N11: 0 | Q11: 0 | T11: 0
A12: ENGINEERING CRAFT | B12: Testing | C12: Taking responsibility | D12: 1 | E12: 0.1 | G12: 1.8 | H12: 0.15 | J12: 2.4 | K12: 0.2 | M12: 2.8 | N12: 0 | Q12: 0 | T12: 0
A13: ENGINEERING CRAFT | B13: Testing | C13: Leading testing strategy | D13: 0 | E13: 0 | G13: 0 | H13: 0 | J13: 1 | K13: 0 | M13: 2.5 | N13: 0.5 | P13: 3.6 | Q13: 0.5 | S13: 4 | T13: 0.5
A14: ENGINEERING CRAFT | B14: Testing | C14: Advocating for testing | D14: 0 | E14: 0 | G14: 0 | H14: 0 | J14: 1 | K14: 0 | M14: 2.5 | N14: 0.5 | P14: 3.6 | Q14: 0.5 | S14: 4 | T14: 0.5
A15: ENGINEERING CRAFT | B15: Technical Understanding & Prioritisation | D15: =D16*E16+D17*E17+D18*E18+D19*E19 -> 1.29 | E15: 0.15 | G15: =G16*H16+G17*H17+G18*H18+G19*H19 -> 2.07 | H15: 0.15 | J15: =J16*K16+J17*K17+J18*K18+J19*K19 -> 2.46 | K15: 0.15 | M15: =M16*N16+M17*N17+M18*N18+M19*N19 -> 3.25 | N15: 0.15 | P15: =P16*Q16+P17*Q17+P18*Q18+P19*Q19 -> 3.705 | Q15: 0.15 | S15: =S16*T16+S17*T17+S18*T18+S19*T19 -> 4 | T15: 0.15
A16: ENGINEERING CRAFT | B16: Technical Understanding & Prioritisation | C16: Understanding code | D16: 1.4 | E16: 0.6 | G16: 2.2 | H16: 0.55 | J16: 2.2 | K16: 0.55 | M16: 3.4 | N16: 0.5 | P16: 3.8 | Q16: 0.5 | S16: 4 | T16: 0.5
A17: ENGINEERING CRAFT | B17: Technical Understanding & Prioritisation | C17: Technical collaboration | D17: 1.2 | E17: 0.25 | G17: 2 | H17: 0.25 | J17: 2.6 | K17: 0.25 | M17: 3.2 | N17: 0.25 | P17: 3.6 | Q17: 0.25 | S17: 4 | T17: 0.25
A18: ENGINEERING CRAFT | B18: Technical Understanding & Prioritisation | C18: Work breakdown | D18: 1 | E18: 0.1 | G18: 1.8 | H18: 0.15 | J18: 2.4 | K18: 0.15 | M18: 3 | N18: 0.15 | P18: 3.5 | Q18: 0.15 | S18: 4 | T18: 0.15
A19: ENGINEERING CRAFT | B19: Technical Understanding & Prioritisation | C19: Task prioritisation | D19: 1 | E19: 0.05 | G19: 1.8 | H19: 0.05 | J19: 2.4 | K19: 0.1 | M19: 3 | N19: 0.1 | P19: 3.8 | Q19: 0.1 | S19: 4 | T19: 0.1
A20: ENGINEERING CRAFT | B20: Software Architecture | D20: =D21*E21+D22*E22+D23*E23+D24*E24+D25*E25 -> 0.9 | E20: 0.1 | G20: =G21*H21+G22*H22+G23*H23+G24*H24+G25*H25 -> 1.45 | H20: 0.12 | J20: =J21*K21+J22*K22+J23*K23+J24*K24+J25*K25 -> 2.17 | K20: 0.15 | M20: =M21*N21+M22*N22+M23*N23+M24*N24+M25*N25 -> 2.78 | N20: 0.15 | P20: =P21*Q21+P22*Q22+P23*Q23+P24*Q24+P25*Q25 -> 3.72 | Q20: 0.15 | S20: =S21*T21+S22*T22+S23*T23+S24*T24+S25*T25 -> 4 | T20: 0.15
A21: ENGINEERING CRAFT | B21: Software Architecture | C21: Reaction to feedback | D21: 2 | E21: 0.3 | G21: 2.5 | H21: 0.25 | J21: 3 | K21: 0.2 | M21: 3.5 | N21: 0 | P21: 3.5 | Q21: 0 | S21: 4 | T21: 0
A22: ENGINEERING CRAFT | B22: Software Architecture | C22: Code | D22: 1 | E22: 0.3 | G22: 1.8 | H22: 0.25 | J22: 2.6 | K22: 0.2 | M22: 3.4 | N22: 0 | P22: 3.6 | Q22: 0 | S22: 4 | T22: 0
A23: ENGINEERING CRAFT | B23: Software Architecture | C23: Design | D23: 0 | E23: 0.2 | G23: 0.5 | H23: 0.25 | J23: 1.5 | K23: 0.3 | M23: 2.5 | N23: 0.4 | P23: 3.8 | Q23: 0.4 | S23: 4 | T23: 0.4
A24: ENGINEERING CRAFT | B24: Software Architecture | C24: Development | D24: 0 | E24: 0.2 | G24: 1 | H24: 0.25 | J24: 2 | K24: 0.3 | M24: 3 | N24: 0.4 | P24: 3.7 | Q24: 0.4 | S24: 4 | T24: 0.4
A25: ENGINEERING CRAFT | B25: Software Architecture | C25: Technical debt | D25: 0.5 | E25: 0 | G25: 1.3 | H25: 0 | J25: 2.1 | K25: 0 | M25: 2.9 | N25: 0.2 | P25: 3.6 | Q25: 0.2 | S25: 4 | T25: 0.2
A26: ENGINEERING CRAFT | B26: Security | D26: =D27*E27+D28*E28+D29*E29+D30*E30+D31*E31+D32*E32 -> 1.28 | E26: 0.1 | G26: =G27*H27+G28*H28+G29*H29+G30*H30+G31*H31+G32*H32 -> 1.995 | H26: 0.1 | J26: =J27*K27+J28*K28+J29*K29+J30*K30+J31*K31+J32*K32 -> 2.71 | K26: 0.1 | M26: =M27*N27+M28*N28+M29*N29+M30*N30+M31*N31+M32*N32 -> 3.19 | N26: 0.1 | P26: =P27*Q27+P28*Q28+P29*Q29+P30*Q30+P31*Q31+P32*Q32 -> 3.62 | Q26: 0.1 | S26: =S27*T27+S28*T28+S29*T29+S30*T30+S31*T31+S32*T32 -> 4 | T26: 0.1
A27: ENGINEERING CRAFT | B27: Security | C27: Knowledge | D27: 1.2 | E27: 0.4 | G27: 2 | H27: 0.35 | J27: 2.8 | K27: 0.3 | M27: 3.6 | N27: 0.3 | P27: 3.6 | Q27: 0.3 | S27: 4 | T27: 0.3
A28: ENGINEERING CRAFT | B28: Security | C28: User data | D28: 1.5 | E28: 0.4 | G28: 2.3 | H28: 0.35 | J28: 3.1 | K28: 0.3 | M28: 3.7 | N28: 0.3 | P28: 3.7 | Q28: 0.3 | S28: 4 | T28: 0.2
A29: ENGINEERING CRAFT | B29: Security | C29: Reporting | D29: 1 | E29: 0.2 | G29: 1.8 | H29: 0.2 | J29: 2.6 | K29: 0.2 | M29: 3.2 | N29: 0 | P29: 3.4 | Q29: 0 | S29: 4 | T29: 0.1
A30: ENGINEERING CRAFT | B30: Security | C30: Proactivity | D30: 0.5 | E30: 0 | G30: 1.3 | H30: 0.1 | J30: 2.1 | K30: 0.2 | M30: 2.9 | N30: 0 | P30: 3.5 | Q30: 0.1 | S30: 4 | T30: 0.1
A31: ENGINEERING CRAFT | B31: Security | C31: Collaboration | D31: 0.8 | E31: 0 | G31: 1.6 | H31: 0 | J31: 2.4 | K31: 0 | M31: 3 | N31: 0 | P31: 3.4 | Q31: 0.1 | S31: 4 | T31: 0.1
A32: ENGINEERING CRAFT | B32: Security | C32: Strategy | D32: 0 | E32: 0 | G32: 0.5 | H32: 0 | J32: 1.5 | K32: 0 | M32: 2.5 | N32: 0.4 | P32: 3.7 | Q32: 0.2 | S32: 4 | T32: 0.2
A33: ENGINEERING CRAFT | B33: Debugging & Monitoring | D33: =D34*E34+D35*E35+D36*E36+D37*E37+D38*E38+D39*E39 -> 1.07 | E33: 0.05 | G33: =G34*H34+G35*H35+G36*H36+G37*H37+G38*H38+G39*H39 -> 1.825 | H33: 0.08 | J33: =J34*K34+J35*K35+J36*K36+J37*K37+J38*K38+J39*K39 -> 2.525 | K33: 0.1 | M33: =M34*N34+M35*N35+M36*N36+M37*N37+M38*N38+M39*N39 -> 2.98 | N33: 0.15 | P33: =P34*Q34+P35*Q35+P36*Q36+P37*Q37+P38*Q38+P39*Q39 -> 3.64 | Q33: 0.15 | S33: =S34*T34+S35*T35+S36*T36+S37*T37+S38*T38+S39*T39 -> 4 | T33: 0.15
A34: ENGINEERING CRAFT | B34: Debugging & Monitoring | C34: Debugging | D34: 1.2 | E34: 0.6 | G34: 2 | H34: 0.55 | J34: 2.8 | K34: 0.4 | M34: 3.4 | N34: 0.3 | P34: 3.8 | Q34: 0.3 | S34: 4 | T34: 0.4
A35: ENGINEERING CRAFT | B35: Debugging & Monitoring | C35: Tools | D35: 1 | E35: 0.3 | G35: 1.8 | H35: 0.25 | J35: 2.6 | K35: 0.2 | M35: 3.2 | N35: 0 | P35: 3.4 | Q35: 0 | S35: 4 | T35: 0
A36: ENGINEERING CRAFT | B36: Debugging & Monitoring | C36: Philosophy | D36: 0.5 | E36: 0.1 | G36: 1.3 | H36: 0.15 | J36: 2.1 | K36: 0.2 | M36: 2.9 | N36: 0.2 | P36: 3.6 | Q36: 0.2 | S36: 4 | T36: 0.2
A37: ENGINEERING CRAFT | B37: Debugging & Monitoring | C37: Data | D37: 0.8 | E37: 0 | G37: 1.6 | H37: 0.05 | J37: 2.4 | K37: 0.15 | M37: 3 | N37: 0.2 | P37: 3.5 | Q37: 0.2 | S37: 4 | T37: 0.2
A38: ENGINEERING CRAFT | B38: Debugging & Monitoring | C38: Profiling | D38: 0.5 | E38: 0 | G38: 1.3 | H38: 0 | J38: 2.1 | K38: 0.05 | M38: 2.9 | N38: 0.2 | P38: 3.7 | Q38: 0.2 | S38: 4 | T38: 0.2
A39: ENGINEERING CRAFT | B39: Debugging & Monitoring | C39: Mentoring | D39: 0 | E39: 0 | G39: 0 | H39: 0 | J39: 1 | K39: 0 | M39: 2 | N39: 0.1 | P39: 3.4 | Q39: 0.1 | S39: 4 | T39: 0
A40: ENGINEERING CRAFT | E40: =E4+E9+E15+E20+E26+E33 -> 1 | H40: =H4+H9+H15+H20+H26+H33 -> 1 | K40: =K4+K9+K15+K20+K26+K33 -> 1 | N40: =N4+N9+N15+N20+N26+N33 -> 1 | Q40: =Q4+Q9+Q15+Q20+Q26+Q33 -> 1 | T40: =T4+T9+T15+T20+T26+T33 -> 1
...

Sheet raw_weights
A1: key | B1: Order | C1: Level | D1: Section | E1: Subsection | F1: Criteria | G1: Role model Rating | H1: Weights | I1: Description
A2: =TRIM(C2&D2&E2&F2) -> Junior DeveloperENGINEERING CRAFT | B2: 0 | C2: Junior Developer | D2: =weights_editor!A3 -> ENGINEERING CRAFT | E2: =weights_editor!B3 | F2: =weights_editor!C3 | G2: =weights_editor!D3 -> 1.26 | H2: =weights_editor!E3 -> 0.7
A3: =C3&D3&E3&F3 -> Junior DeveloperENGINEERING CRAFTWriting Code | B3: 1 | C3: Junior Developer | D3: =weights_editor!A4 -> ENGINEERING CRAFT | E3: =weights_editor!B4 -> Writing Code | F3: =weights_editor!C4 | G3: =weights_editor!D4 -> 1.2 | H3: =weights_editor!E4 -> 0.45 | I3: The ability to contribute high quality code to production environments. Is able to consistently write testable, readable code across larger more complex projects.
A4: =C4&D4&E4&F4 -> Junior DeveloperENGINEERING CRAFTWriting CodeQuality | B4: 2 | C4: Junior Developer | D4: =weights_editor!A5 -> ENGINEERING CRAFT | E4: =weights_editor!B5 -> Writing Code | F4: =weights_editor!C5 -> Quality | G4: =weights_editor!D5 -> 1.2 | H4: =weights_editor!E5 -> 0.5 | I4: Your code has always followed correct convention, requiring only minor improvements. You've made trade-offs knowingly.
A5: =C5&D5&E5&F5 -> Junior DeveloperENGINEERING CRAFTWriting CodeDocumentation | B5: 3 | C5: Junior Developer | D5: =weights_editor!A6 -> ENGINEERING CRAFT | E5: =weights_editor!B6 -> Writing Code | F5: =weights_editor!C6 -> Documentation | G5: =weights_editor!D6 -> 1 | H5: =weights_editor!E6 -> 0.25 | I5: You've regularly documented your code and looked to improve documentation elsewhere.
A6: =C6&D6&E6&F6 -> Junior DeveloperENGINEERING CRAFTWriting CodeLanguage | B6: 4 | C6: Junior Developer | D6: =weights_editor!A7 -> ENGINEERING CRAFT | E6: =weights_editor!B7 -> Writing Code | F6: =weights_editor!C7 -> Language | G6: =weights_editor!D7 -> 1.4 | H6: =weights_editor!E7 -> 0.25 | I6: You're committing quality code in at least one language and have a working understanding of other languages your team needs.
A7: =C7&D7&E7&F7 -> Junior DeveloperENGINEERING CRAFTWriting CodeMentoring | B7: 5 | C7: Junior Developer | D7: =weights_editor!A8 -> ENGINEERING CRAFT | E7: =weights_editor!B8 -> Writing Code | F7: =weights_editor!C8 -> Mentoring | G7: =weights_editor!D8 -> 0 | H7: =weights_editor!E8 -> 0 | I7: N/A
A8: =C8&D8&E8&F8 -> Junior DeveloperENGINEERING CRAFTTesting | B8: 6 | C8: Junior Developer | D8: =weights_editor!A9 -> ENGINEERING CRAFT | E8: =weights_editor!B9 -> Testing | F8: =weights_editor!C9 | G8: =weights_editor!D9 -> 1.7 | H8: =weights_editor!E9 -> 0.15 | I8: The ability to understand and implement great testing practices. Understands how to test code, and the valuable role that testing plays.
A9: =C9&D9&E9&F9 -> Junior DeveloperENGINEERING CRAFTTestingTesting your code | B9: 7 | C9: Junior Developer | D9: =weights_editor!A10 -> ENGINEERING CRAFT | E9: =weights_editor!B10 -> Testing | F9: =weights_editor!C10 -> Testing your code | G9: =weights_editor!D10 -> 2 | H9: =weights_editor!E10 -> 0.7 | I9: You consistently write solid unit tests, sometimes with help from more senior engineers.
A10: =C10&D10&E10&F10 -> Junior DeveloperENGINEERING CRAFTTestingImproving coverage | B10: 8 | C10: Junior Developer | D10: =weights_editor!A11 -> ENGINEERING CRAFT | E10: =weights_editor!B11 -> Testing | F10: =weights_editor!C11 -> Improving coverage | G10: =weights_editor!D11 -> 1 | H10: =weights_editor!E11 -> 0.2 | I10: You've spotted small areas of low test coverage and patched them.
A11: =C11&D11&E11&F11 -> Junior DeveloperENGINEERING CRAFTTestingTaking responsibility | B11: 9 | C11: Junior Developer | D11: =weights_editor!A12 -> ENGINEERING CRAFT | E11: =weights_editor!B12 -> Testing | F11: =weights_editor!C12 -> Taking responsibility | G11: =weights_editor!D12 -> 1 | H11: =weights_editor!E12 -> 0.1 | I11: You've consistently ensured that your code passes tests before creating or merging pull requests
A12: =C12&D12&E12&F12 -> Junior DeveloperENGINEERING CRAFTTestingLeading testing strategy | B12: 10 | C12: Junior Developer | D12: =weights_editor!A13 -> ENGINEERING CRAFT | E12: =weights_editor!B13 -> Testing | F12: =weights_editor!C13 -> Leading testing strategy | G12: =weights_editor!D13 -> 0 | H12: =weights_editor!E13 -> 0 | I12: N/A
A13: =C13&D13&E13&F13 -> Junior DeveloperENGINEERING CRAFTTestingAdvocating for testing | B13: 11 | C13: Junior Developer | D13: =weights_editor!A14 -> ENGINEERING CRAFT | E13: =weights_editor!B14 -> Testing | F13: =weights_editor!C14 -> Advocating for testing | G13: =weights_editor!D14 -> 0 | H13: =weights_editor!E14 -> 0 | I13: N/A
A14: =C14&D14&E14&F14 -> Junior DeveloperENGINEERING CRAFTTechnical Understanding & Prioritisation | B14: 12 | C14: Junior Developer | D14: =weights_editor!A15 -> ENGINEERING CRAFT | E14: =weights_editor!B15 -> Technical Understanding & Prioritisation | F14: =weights_editor!C15 | G14: =weights_editor!D15 -> 1.29 | H14: =weights_editor!E15 -> 0.15 | I14: The ability to develop technical understanding and use this to prioritise tasks appropriately. Shows some confidence in technical understanding including the importance of prioritisation.
... A38: =C38&D38&E38&F38 -> Junior DeveloperENGINEERING CRAFTDebugging & MonitoringMentoring | B38: 36 | C38: Junior Developer | D38: =weights_editor!A39 -> ENGINEERING CRAFT | E38: =weights_editor!B39 -> Debugging & Monitoring | F38: =weights_editor!C39 -> Mentoring | G38: =weights_editor!D39 -> 0 | H38: =weights_editor!E39 -> 0 | I38: N/A
A39: =C39&D39&E39&F39 -> Junior DeveloperSOFT SKILLS | B39: 37 | C39: Junior Developer | D39: =weights_editor!A41 -> SOFT SKILLS | E39: =weights_editor!B41 | F39: =weights_editor!C41 | G39: =weights_editor!D41 -> 1.2286 | H39: =weights_editor!E41 -> 0.25
A40: =C40&D40&E40&F40 -> Junior DeveloperSOFT SKILLSEmpathy & Humility | B40: 38 | C40: Junior Developer | D40: =weights_editor!A42 -> SOFT SKILLS | E40: =weights_editor!B42 -> Empathy & Humility | F40: =weights_editor!C42 | G40: =weights_editor!D42 -> 0.85 | H40: =weights_editor!E42 -> 0.4 | I40: The ability to share someone else's feelings or experiences by imagining what it would be like to be in that person's situation. Constantly pushes for a better understanding of the needs and perspectives of those outside their own viewpoint.
A41: =C41&D41&E41&F41 -> Junior DeveloperSOFT SKILLSEmpathy & HumilityCredit and blame | B41: 39 | C41: Junior Developer | D41: =weights_editor!A43 -> SOFT SKILLS | E41: =weights_editor!B43 -> Empathy & Humility | F41: =weights_editor!C43 -> Credit and blame | G41: =weights_editor!D43 -> 1 | H41: =weights_editor!E43 -> 0.3 | I41: You actively look to ensure praise is shared fairly when given to you. If someone else is blamed for your mistake, you own up.
A42: =C42&D42&E42&F42 -> Junior DeveloperSOFT SKILLSEmpathy & HumilityUnderstanding others | B42: 40 | C42: Junior Developer | D42: =weights_editor!A44 -> SOFT SKILLS | E42: =weights_editor!B44 -> Empathy & Humility | F42: =weights_editor!C44 -> Understanding others | G42: =weights_editor!D44 -> 1.5 | H42: =weights_editor!E44 -> 0.3 | I42: You regularly and actively ask others for their opinions with the goal of better understanding where they're coming from.
A43: =C43&D43&E43&F43 -> Junior DeveloperSOFT SKILLSEmpathy & HumilityMediation and facilitation | B43: 41 | C43: Junior Developer | D43: =weights_editor!A45 -> SOFT SKILLS | E43: =weights_editor!B45 -> Empathy & Humility | F43: =weights_editor!C45 -> Mediation and facilitation | G43: =weights_editor!D45 -> 0.5 | H43: =weights_editor!E45 -> 0.2 | I43: You have de-escalated disagreements amongst your peers, looking for common ground.
A44: =C44&D44&E44&F44 -> Junior DeveloperSOFT SKILLSEmpathy & HumilityMentoring | B44: 42 | C44: Junior Developer | D44: =weights_editor!A46 -> SOFT SKILLS | E44: =weights_editor!B46 -> Empathy & Humility | F44: =weights_editor!C46 -> Mentoring | G44: =weights_editor!D46 -> 0 | H44: =weights_editor!E46 -> 0.2 | I44: You've proactively developed at least one informal mentoring relationship through your ability to understand a peer or subordinate.
A45: =C45&D45&E45&F45 -> Junior DeveloperSOFT SKILLSCommunication | B45: 43 | C45: Junior Developer | D45: =weights_editor!A47 -> SOFT SKILLS | E45: =weights_editor!B47 -> Communication | F45: =weights_editor!C47 | G45: =weights_editor!D47 -> 1.25 | H45: =weights_editor!E47 -> 0.3 | I45: The ability to communicate well with those around you with sensitivity to timeliness, medium, brevity and tone. Communicates with wider team, feeds back on communication of others.
A46: =C46&D46&E46&F46 -> Junior DeveloperSOFT SKILLSCommunicationKeeping people informed | B46: 44 | C46: Junior Developer | D46: =weights_editor!A48 -> SOFT SKILLS | E46: =weights_editor!B48 -> Communication | F46: =weights_editor!C48 -> Keeping people informed | G46: =weights_editor!D48 -> 1.2 | H46: =weights_editor!E48 -> 0.5 | I46: You communicate work updates from your peers across your wider team, and respond to feedback in a timely manner.
A47: =C47&D47&E47&F47 -> Junior DeveloperSOFT SKILLSCommunicationLooking for feedback | B47: 45 | C47: Junior Developer | D47: =weights_editor!A49 -> SOFT SKILLS | E47: =weights_editor!B49 -> Communication | F47: =weights_editor!C49 -> Looking for feedback | G47: =weights_editor!D49 -> 2 | H47: =weights_editor!E49 -> 0.3 | I47: You consistently ask for critique on your thinking from a wider group, and inform the group which elements you're incorporating into your work.
A48: =C48&D48&E48&F48 -> Junior DeveloperSOFT SKILLSCommunicationDelivering bad news | B48: 46 | C48: Junior Developer | D48: =weights_editor!A50 -> SOFT SKILLS | E48: =weights_editor!B50 -> Communication | F48: =weights_editor!C50 -> Delivering bad news | G48: =weights_editor!D50 -> 0.5 | H48: =weights_editor!E50 -> 0.1 | I48: You recognise when you need help from outside your immediate peers and asked for it effectively.
A49: =C49&D49&E49&F49 -> Junior DeveloperSOFT SKILLSCommunicationMentoring communicators | B49: 47 | C49: Junior Developer | D49: =weights_editor!A51 -> SOFT SKILLS | E49: =weights_editor!B51 -> Communication | F49: =weights_editor!C51 -> Mentoring communicators | G49: =weights_editor!D51 -> 0 | H49: =weights_editor!E51 -> 0.1 | I49: You are able to unpick the communication of others around you and offer advice and feedback.
A50: =C50&D50&E50&F50 -> Junior DeveloperSOFT SKILLSInitiative | B50: 48 | C50: Junior Developer | D50: =weights_editor!A52 -> SOFT SKILLS | E50: =weights_editor!B52 -> Initiative | F50: =weights_editor!C52 | G50: =weights_editor!D52 -> 1.85 | H50: =weights_editor!E52 -> 0.2 | I50: The ability to use your judgment to make decisions and do things without needing to be told what to do. Doesn't wait to be asked. Open minded about their own skillset.
A51: =C51&D51&E51&F51 -> Junior DeveloperSOFT SKILLSInitiativeCan-do attitude | B51: 49 | C51: Junior Developer | D51: =weights_editor!A53 -> SOFT SKILLS | E51: =weights_editor!B53 -> Initiative | F51: =weights_editor!C53 -> Can-do attitude | G51: =weights_editor!D53 -> 2 | H51: =weights_editor!E53 -> 0.6 | I51: You repeatedly demonstrate a positive attitude when given new projects.
... A58: =C58&D58&E58&F58 -> Junior DeveloperSOFT SKILLSObjectivity & AdaptabilityTime management | B58: 56 | C58: Junior Developer | D58: =weights_editor!A60 -> SOFT SKILLS | E58: =weights_editor!B60 -> Objectivity & Adaptability | F58: =weights_editor!C60 -> Time management | G58: =weights_editor!D60 -> 1.4 | H58: =weights_editor!E60 -> 0.05 | I58: You look to reduce or change the scope of your work to meet a timeline or criteria not set by you.
A59: =C59&D59&E59&F59 -> Junior DeveloperSOFT SKILLSBusiness Acumen | B59: 57 | C59: Junior Developer | D59: =weights_editor!A61 -> SOFT SKILLS | E59: =weights_editor!B61 -> Business Acumen | F59: =weights_editor!C61 | G59: =weights_editor!D61 -> 1 | H59: =weights_editor!E61 -> 0.02
A60: =C60&D60&E60&F60 -> Junior DeveloperSOFT SKILLSBusiness AcumenUnderstanding level | B60: 58 | C60: Junior Developer | D60: =weights_editor!A62 -> SOFT SKILLS | E60: =weights_editor!B62 -> Business Acumen | F60: =weights_editor!C62 -> Understanding level | G60: =weights_editor!D62 -> 1 | H60: =weights_editor!E62 -> 1 | I60: Has a basic understanding of their team's domain and related marketplace.
A61: =C61&D61&E61&F61 -> Junior DeveloperLEADERSHIP | B61: 59 | C61: Junior Developer | D61: =weights_editor!A64 -> LEADERSHIP | E61: =weights_editor!B64 | F61: =weights_editor!C64 | G61: =weights_editor!D64 -> 0.529 | H61: =weights_editor!E64 -> 0.05
A62: =C62&D62&E62&F62 -> Junior DeveloperLEADERSHIPHiring and Org Design | B62: 60 | C62: Junior Developer | D62: =weights_editor!A65 -> LEADERSHIP | E62: =weights_editor!B65 -> Hiring and Org Design | F62: =weights_editor!C65 | G62: =weights_editor!D65 -> 0 | H62: =weights_editor!E65 -> 0.2 | I62: The ability to understand the needs of the business and ensure that your team can meet them. A competent interviewer. Able to follow a structured hiring process, and make a decision.
A63: =C63&D63&E63&F63 -> Junior DeveloperLEADERSHIPHiring and Org DesignDeploying Teams | B63: 61 | C63: Junior Developer | D63: =weights_editor!A66 -> LEADERSHIP | E63: =weights_editor!B66 -> Hiring and Org Design | F63: =weights_editor!C66 -> Deploying Teams | G63: =weights_editor!D66 -> 0 | H63: =weights_editor!E66 -> 0.4 | I63: N/A
A64: =C64&D64&E64&F64 -> Junior DeveloperLEADERSHIPHiring and Org DesignEmployer Brand | B64: 62 | C64: Junior Developer | D64: =weights_editor!A67 -> LEADERSHIP | E64: =weights_editor!B67 -> Hiring and Org Design | F64: =weights_editor!C67 -> Employer Brand | G64: =weights_editor!D67 -> 0 | H64: =weights_editor!E67 -> 0.4 | I64: N/A
A65: =C65&D65&E65&F65 -> Junior DeveloperLEADERSHIPHiring and Org DesignHiring | B65: 63 | C65: Junior Developer | D65: =weights_editor!A68 -> LEADERSHIP | E65: =weights_editor!B68 -> Hiring and Org Design | F65: =weights_editor!C68 -> Hiring | G65: =weights_editor!D68 -> 0 | H65: =weights_editor!E68 -> 0.2 | I65: N/A
A66: =C66&D66&E66&F66 -> Junior DeveloperLEADERSHIPStakeholder Management | B66: 64 | C66: Junior Developer | D66: =weights_editor!A69 -> LEADERSHIP | E66: =weights_editor!B69 -> Stakeholder Management | F66: =weights_editor!C69 | G66: =weights_editor!D69 -> 0.73 | H66: =weights_editor!E69 -> 0.3 | I66: The ability to ensure that teams are protected and expectations are set correctly. Is able to keep tangential teams informed and expectations managed around everyday work updates. Uses judgement about others' reaction when disclosing information and opinions.
A67: =C67&D67&E67&F67 -> Junior DeveloperLEADERSHIPStakeholder ManagementManaging Goals and Expectations | B67: 65 | C67: Junior Developer | D67: =weights_editor!A70 -> LEADERSHIP | E67: =weights_editor!B70 -> Stakeholder Management | F67: =weights_editor!C70 -> Managing Goals and Expectations | G67: =weights_editor!D70 -> 0.5 | H67: =weights_editor!E70 -> 0.4 | I67: You lead on successful projects with external clients, internal stakeholders or partners with a successful outcome, ensuring goals are understood throughout.
A68: =C68&D68&E68&F68 -> Junior DeveloperLEADERSHIPStakeholder ManagementForesight | B68: 66 | C68: Junior Developer | D68: =weights_editor!A71 -> LEADERSHIP | E68: =weights_editor!B71 -> Stakeholder Management | F68: =weights_editor!C71 -> Foresight | G68: =weights_editor!D71 -> 0.8 | H68: =weights_editor!E71 -> 0.3 | I68: You work to inform departments, stakeholders or clients of an issue they face without being asked or expected to do so.
A69: =C69&D69&E69&F69 -> Junior DeveloperLEADERSHIPStakeholder ManagementEngendering Trust | B69: 67 | C69: Junior Developer | D69: =weights_editor!A72 -> LEADERSHIP | E69: =weights_editor!B72 -> Stakeholder Management | F69: =weights_editor!C72 -> Engendering Trust | G69: =weights_editor!D72 -> 1.2 | H69: =weights_editor!E72 -> 0.2 | I69: You bring stakeholders or clients into a process in a way that makes best use of their time and their strengths.
...

Sheet Base career path evaluation gri
A1: SKILLS | AG1: April 2022 | AI1: CONFIRMED | AK1: July 2022 | AM1: SENIOR | AO1: LEGEND
C2: Junior Software Engineer (associate) | I2: Confirmed Software Engineer | O2: Senior Software Engineer | U2: Lead Software Engineer | AA2: Principal Software Engineer | AG2: Level | AH2: Success | AI2: Ideas for improvements | AK2: Level | AL2: Success | AM2: Ideas for improvements
A3: SOFT SKILLS | AO3: LIVE CURSOR
A4: Empathy & Humility | AG4: 🆙 3 / 2 | AH4: This is great! Focus elsewhere. | AO4: 🖐 | AP4: Tells current position on this skills.
A5: The ability to share someone else's feelings or experiences by imagining what it would be like to be in that person's situation | C5: Constantly pushes for a better understanding of the needs and perspectives of those outside their own viewpoint. | I5: Constantly pushes for a better understanding of the needs and perspectives of those outside their own viewpoint. | O5: A great person to have in any room. Trusted by peers and their team. Can take any problem team and help them drive in the same direction. | U5: Often found advocating for and representing others in conversations they cannot be in. Helps leaders to understand their teams, users and clients. | AA5: Often found advocating for and representing others in conversations they cannot be in. Helps leaders to understand their teams, users and clients. | AH5: - item 1 - item 2 | AI5: - Q1 : TBD - Q2 : TBD
C6: • Credit and blame: You actively look to ensure praise is shared fairly when given to you. If someone else is blamed for your mistake, you own up. • Understanding others: You regularly and actively ask others for their opinions with the goal of better understanding where they're coming from. • Mediation and facilitation: You have de-escalated disagreements amongst your peers, looking for common ground. • Mentoring: You've proactively developed at least one informal mentoring relationship through your ability to understand a peer or subordinate. | I6: • Credit and blame: You actively look to ensure praise is shared fairly when given to you. If someone else is blamed for your mistake, you own up. • Understanding others: You regularly and actively ask others for their opinions with the goal of better understanding where they're coming from. • Mediation and facilitation: You have de-escalated disagreements amongst your peers, looking for common ground. • Mentoring: You've proactively developed at least one informal mentoring relationship through your ability to understand a peer or subordinate. | O6: • Credit and blame: You're an ally to your peers and wider team, protecting them from undue blame and pushing praise onto them. You regularly look for opportunities to give praise publicly. • Understanding others: You are able to recognise bias in others and help them to see their peers, customers or stakeholders through fresh eyes. • Mediation and facilitation: You help teams within your organisation get closer to each other and understand each other's viewpoints. • Mentoring: You've proactively developed multiple informal or formal mentoring relationship through your ability to understand a peer or subordinate. | U6: • Credit and blame: You use your position of power to redirect credit fairly, and absorb blame that isn't constructive to your team. • Understanding others: You're called for when any team wants to understand a group of people better. You can point to ways in which you've actively looked to dramatically improve the empathy of your organisation. • Mediation and facilitation: You're called on to facilitate groups of people, often outside your peers, due to your calm and thoughtful demeanour. You make even combative people feel calm through finding common ground. • Mentoring: You have several formal mentoring relationships with senior staff both within and outside your immediate team. | AA6: • Credit and blame: You use your position of power to redirect credit fairly, and absorb blame that isn't constructive to your team. • Understanding others: You're called for when any team wants to understand a group of people better. You can point to ways in which you've actively looked to dramatically improve the empathy of your organisation. • Mediation and facilitation: You're called on to facilitate groups of people, often outside your peers, due to your calm and thoughtful demeanour. You make even combative people feel calm through finding common ground. • Mentoring: You have several formal mentoring relationships with senior staff both within and outside your immediate team.
A7: Communication | AG7: ⚠️ 1 / 2 | AH7: Need to work on this to evolve
A8: The ability to communicate well with those around you with sensitivity to timeliness, medium, brevity and tone | C8: Communicates with wider team, feeds back on communication of others. | I8: Communicates with wider team, feeds back on communication of others. | O8: Communicates with organisation, helps others in team to communicate | U8: Communicates with organisation, helps others in team to communicate | AA8: Communicates with the wider business, including change affecting the work of others, helps teams around them to communicate better. | AH8: - item 1 - item 2 | AI8: - Q1 : TBD - Q2 : TBD
C9: • Keeping people informed: You communicate work updates from your peers across your wider team, and respond to feedback in a timely manner. • Looking for feedback: You consistently ask for critique on your thinking from a wider group, and inform the group which elements you're incorporating into your work. • Delivering bad news: You recognise when you need help from outside your immediate peers and asked for it effectively. • Mentoring communicators: You are able to unpick the communication of others around you and offer advice and feedback. | I9: • Keeping people informed: You communicate work updates from your peers across your wider team, and respond to feedback in a timely manner. • Looking for feedback: You consistently ask for critique on your thinking from a wider group, and inform the group which elements you're incorporating into your work. • Delivering bad news: You recognise when you need help from outside your immediate peers and asked for it effectively. • Mentoring communicators: You are able to unpick the communication of others around you and offer advice and feedback. | O9: • Keeping people informed: You communicate on behalf of your team to the broader organisation on important or divisive projects, handling any questions in a timely manner. • Looking for feedback: You proactively ask for feedback from important stakeholders in your organisation early in your work. • Delivering bad news: You communicate changes of plan or slip in timelines to a broad group within your organisation and manage expectations effectively until resolution. • Mentoring communicators: You set up processes around more effective communication for your immediate team, and manage its implementation. You proactively offer good feedback to peers on their communication methods. | U9: • Keeping people informed: You communicate on behalf of your team to the broader organisation on important or divisive projects, handling any questions in a timely manner. • Looking for feedback: You proactively ask for feedback from important stakeholders in your organisation early in your work. • Delivering bad news: You communicate changes of plan or slip in timelines to a broad group within your organisation and manage expectations effectively until resolution. • Mentoring communicators: You set up processes around more effective communication for your immediate team, and manage its implementation. You proactively offer good feedback to peers on their communication methods. | AA9: • Keeping people informed: You design the process of communication to communicate with the business around strategically important projects using appropriate mediums. • Looking for feedback: You communicate changes in plans, organisational structure or work situation which directly affects one or more people, and manage any fall out from that change ensuring all parties stay informed and content. • Delivering bad news: You communicate bad news to a group of reports or peers, ensuring that a strategy is in place to manage expectations and morale during the change. Your approach involves thoughtfully designed communication to the top levels of the organisation • Mentoring communicators: You regularly mentor others on communication technique, unpick poor communication in your wider organisation and add process where needed. You're comfortable feeding back on the communication of your seniors.
A10: Initiative | AG10: 🆙 3 / 2 | AH10: This is great! KEEP UP! | AO10: HISTORY
A11: The ability to use your judgment to make decisions and do things without needing to be told what to do | C11: Doesn't wait to be asked. Open minded about their own skillset. | I11: Relentlessly positive in pursuing new ways to solve a problem. | O11: Refuses to believe that anything is unachievable. Infectious desire to activate and progress. Drives others to create their best work. Like a rocket: just light the fuse. | U11: Refuses to believe that anything is unachievable. Infectious desire to activate and progress. Drives others to create their best work. Like a rocket: just light the fuse. | AA11: Asks a lot, expects the impossible. Drives others to create their best work. Sees opportunities in everything. | AH11: - item 1 - item 2 | AI11: - Q1 : TBD - Q2 : TBD
C12: • Can-do attitude: You repeatedly demonstrate a positive attitude when given new projects. • Pro-activity in seeking help: If you're stuck on something, you seek help quickly from the correct party. • Follow through: You've taken on a small piece of work with ill-defined or unknown requirements and helped to push through to a successful outcome. | I12: • Can-do attitude: You see opportunity in every piece of work, however outwardly mundane or solved. • Pro-activity in seeking help: When your team is stuck on something, you are quick to suggest that you all adjust focus, reframe a problem or talk to someone new. • Follow through: You lead medium to large projects with unknown requirements and helped drive to a successful outcome. | O12: • Can-do attitude: You're constantly creating new opportunities for yourself and those around you. Your team is celebrated for innovation as a result of your contributions. • Pro-activity in seeking help: You recognise a lack of expertise in yourself and your organisation, and pro-actively found that expertise in areas not given to you. This leads to a successful outcome on more than one occasion. • Follow through: You adapt your skillset and knowledge to lead large or complex projects to a successful outcome. | U12: • Can-do attitude: You're constantly creating new opportunities for yourself and those around you. Your team is celebrated for innovation as a result of your contributions. • Pro-activity in seeking help: You recognise a lack of expertise in yourself and your organisation, and pro-actively found that expertise in areas not given to you. This leads to a successful outcome on more than one occasion. • Follow through: You adapt your skillset and knowledge to lead large or complex projects to a successful outcome. | AA12: • Can-do attitude: YYou take ill-defined requirements and lead a large group within your organisation to make progress on them. • Pro-activity in seeking help: You build relationships with people across your organisation without being asked, expressly for the purpose of boosting your ability to achieve great results. • Follow through: You're deeply involved in projects which require your ability to move through uncertainty. You adapt your skillset appropriately for those projects, morphing into what the projects need you to be.
A13: Objectivity & Adaptability | AG13: ✅ 2 / 2 | AO13: 🆙 2 / 1 | AP13: Above expectations.
A14: The ability to deal with problems based on conditions that really exist, rather than following fixed theories, ideas, or rules, and to adapt to suit different conditions | C14: Able to be objective in evaluating their own work and comfortable and accepting of new contexts and roles. | I14: Is able to change their mind over strongly-held beliefs and pursue a new path with no loss of velocity. | O14: Can take problems outside their skillset and quickly adapt to solve them. Helps other peers to do the same. | U14: Leads others in looking for ways to better serve business or customer needs, even outside their own discipline. Willing to lead mundane but important tasks and help whole teams to move on their goals through simplifying and breaking down problems. | AA14: ← | AH14: - item 1 - item 2 | AI14: - Q1 : TBD - Q2 : TBD
C15: • Efficient decision-making: You regularly make decisions regarding the direction of your own work in a timely manner. • Self improvement: You can name three activities which give you energy, and three which drain you. • Objectivity: You allow your plan to be changed by new information. • Time management: You look to reduce or change the scope of your work to meet a timeline or criteria not set by you. | I15: • Efficient decision-making: You help your immediate peers to make decisions based on what projects need, not what they feel most comfortable doing. • Self improvement: You use your development areas to build improvement goals for yourself and see improvements over time. • Objectivity: You look for new information, assuming that you don't know everything. You can point to examples when you had a strong opinion changed for the better. • Time management: You actively flag when you think something can be achieved more quickly, even if it was your plan initially and it will involve admitting fault. | O15: • Efficient decision-making: You help your team to make decisions in a more timely manner, breaking down assumptions about the shape of the work and encouraging people to value done over perfect. • Self improvement: You can point to several areas of improvement resulting from your focus on improving development areas over time. • Objectivity: You are positive in the face of dramatic changes of plans. Curveballs are dealt with sensibly without frustration. • Time management: You're in control of your calendar. You take no issue with not being involved in a project or meeting if it means saving you time. | U15: • Efficient decision-making: You're part of decision-making teams on several major company-wide initiatives, employing appropriate processes and techniques. • Self improvement: You build processes for yourself and others around you, diagnosing development areas and figuring out better ways of working and collaborating. You champion self improvement in your organisation. • Objectivity: You know which hills to die on. You recognise the importance of believability and pragmatism as a tool for moving product and business forwards, and when to stand your ground. • Time management: You are constantly checking your own plans and the plans of your team for opportunities to change or reduce effort. You exclusively pick up the most important, not the most interesting tasks. | AA15: ←
A16: Business Acumen | AG16: ✅ 2 / 2 | AO16: ✅ 1 / 1 | AP16: Meet expectations.
C17: Has a basic understanding of their team's domain and related marketplace. | I17: Has a basic understanding of their team's domain, and how it contributes to overall business strategy. | O17: Has a thorough understanding of their team's domain, and how it contributes to overall business strategy. Has a basic understanding of adjacent teams' business domains. | U17: Has a thorough understanding of their team's domain, and how it contributes to overall business strategy. Has a basic understanding of adjacent teams' business domains. | AA17: Has a thourough understanding of their team's domain, strategy, and how it maps to overall market trends. Has a thorough understanding of adjacent teams' strategies and how they map to their team and interaction points. | AH17: - item 1 - item 2 | AI17: - Q1 : TBD - Q2 : TBD
AO19: ⚠️ 0 / 1 | AP19: Below expectations.
A20: ENGINEERING CRAFT
A21: Writing Code | AG21: ✅ 5 / 3
A22: The ability to contribute high quality code to production environments | C22: Is able to consistently write testable, readable code across larger more complex projects | I22: Is able to consistently write production-ready code across large, complex projects | O22: Is able to consistently write production-ready code across large, complex projects | U22: Is a go-to within the team and the wider organization across multiple codebases and languages. | AA22: Is an exceptional engineer beyond the organization, contributing to pushing the craft forwards | AH22: - item 1 - item 2 | AI22: - Q1 : TBD - Q2 : TBD
C23: • Quality: Your code has always followed correct convention, requiring only minor improvements. You've made trade-offs knowingly. • Documentation: You've regularly documented your code and looked to improve documentation elsewhere. • Language: You're committing quality code in at least one language and have a working understanding of other languages your team needs | I23: • Quality: You're regularly trusted to lead complex and business-critical coding projects, including guiding others. • Documentation: Your code is consistently self-documenting where possible. You've regularly maintained, improved and extended existing documentation unprompted. • Language: You're committing quality code in any language your team needs OR you're best in class at one language • Mentoring: You have mentored several junior engineers around code quality | O23: • Quality: You're regularly trusted to lead complex and business-critical coding projects, including guiding others. • Documentation: Your code is consistently self-documenting where possible. You've regularly maintained, improved and extended existing documentation unprompted. • Language: You're committing quality code in any language your team needs OR you're best in class at one language • Mentoring: You have mentored several junior engineers around code quality | U23: • Quality: You're known as a hub of code knowledge across multiple teams, proposing and owning the implementation of new languages and technologies where appropriate • Documentation: You've organised documentation for large code projects efficiently, advising others on best practices where needed. • Language: You're best in class at your language of choice, and are committing quality code in other languages the organization needs. • Mentoring: You've actively mentored multiple senior engineers across the organization around code quality | AA23: • Quality: You've pushed the boundaries of the organization's coding practices, extending languages and libraries where needed. • Documentation: You've led efforts to improve documentation and code skills across the organization. You've actively pushed other engineers to improve how code is understood and read. • Language: You're contributing to the languages that your company uses, developing new patterns and paradigms to solve real business needs. • Mentoring: You're regularly mentoring mentors, raising the quality of every team member's code
A24: Testing | AG24: ✅ 5 / 3
A25: The ability to understand and implement great testing practices | C25: Understands how to test code, and the valuable role that testing plays | I25: Understands the importance of a testing strategy, with growing levels of autonomy | O25: Independently testing, advising the rest of the team on quality of tests | U25: A growing leader within the team around testing strategy | AA25: A leader within the organization in terms of test strategy | AH25: - item 1 - item 2 | AI25: - Q1 : TBD - Q2 : TBD
